INFO:django.utils.autoreload:C:\Users\Desktop\Projects\Django Framework\Learn\ScrapeProject\src\scraper\views.py changed, reloading.
INFO:django.utils.autoreload:C:\Users\Desktop\Projects\Django Framework\Learn\ScrapeProject\src\scraper\views.py changed, reloading.
ERROR:django.request:Internal Server Error: /website/scraper/engine/
Traceback (most recent call last):
  File "C:\Users\Desktop\Projects\Django Framework\Learn\ScrapeProject\myenv\lib\site-packages\urllib3\connectionpool.py", line 600, in urlopen
    chunked=chunked)
  File "C:\Users\Desktop\Projects\Django Framework\Learn\ScrapeProject\myenv\lib\site-packages\urllib3\connectionpool.py", line 343, in _make_request
    self._validate_conn(conn)
  File "C:\Users\Desktop\Projects\Django Framework\Learn\ScrapeProject\myenv\lib\site-packages\urllib3\connectionpool.py", line 839, in _validate_conn
    conn.connect()
  File "C:\Users\Desktop\Projects\Django Framework\Learn\ScrapeProject\myenv\lib\site-packages\urllib3\connection.py", line 344, in connect
    ssl_context=context)
  File "C:\Users\Desktop\Projects\Django Framework\Learn\ScrapeProject\myenv\lib\site-packages\urllib3\util\ssl_.py", line 344, in ssl_wrap_socket
    return context.wrap_socket(sock, server_hostname=server_hostname)
  File "c:\users\user\appdata\local\programs\python\python36\Lib\ssl.py", line 407, in wrap_socket
    _context=self, _session=session)
  File "c:\users\user\appdata\local\programs\python\python36\Lib\ssl.py", line 814, in __init__
    self.do_handshake()
  File "c:\users\user\appdata\local\programs\python\python36\Lib\ssl.py", line 1068, in do_handshake
    self._sslobj.do_handshake()
  File "c:\users\user\appdata\local\programs\python\python36\Lib\ssl.py", line 689, in do_handshake
    self._sslobj.do_handshake()
ConnectionResetError: [WinError 10054] An existing connection was forcibly closed by the remote host

During handling of the above exception, another exception occurred:

Traceback (most recent call last):
  File "C:\Users\Desktop\Projects\Django Framework\Learn\ScrapeProject\myenv\lib\site-packages\requests\adapters.py", line 449, in send
    timeout=timeout
  File "C:\Users\Desktop\Projects\Django Framework\Learn\ScrapeProject\myenv\lib\site-packages\urllib3\connectionpool.py", line 638, in urlopen
    _stacktrace=sys.exc_info()[2])
  File "C:\Users\Desktop\Projects\Django Framework\Learn\ScrapeProject\myenv\lib\site-packages\urllib3\util\retry.py", line 367, in increment
    raise six.reraise(type(error), error, _stacktrace)
  File "C:\Users\Desktop\Projects\Django Framework\Learn\ScrapeProject\myenv\lib\site-packages\urllib3\packages\six.py", line 685, in reraise
    raise value.with_traceback(tb)
  File "C:\Users\Desktop\Projects\Django Framework\Learn\ScrapeProject\myenv\lib\site-packages\urllib3\connectionpool.py", line 600, in urlopen
    chunked=chunked)
  File "C:\Users\Desktop\Projects\Django Framework\Learn\ScrapeProject\myenv\lib\site-packages\urllib3\connectionpool.py", line 343, in _make_request
    self._validate_conn(conn)
  File "C:\Users\Desktop\Projects\Django Framework\Learn\ScrapeProject\myenv\lib\site-packages\urllib3\connectionpool.py", line 839, in _validate_conn
    conn.connect()
  File "C:\Users\Desktop\Projects\Django Framework\Learn\ScrapeProject\myenv\lib\site-packages\urllib3\connection.py", line 344, in connect
    ssl_context=context)
  File "C:\Users\Desktop\Projects\Django Framework\Learn\ScrapeProject\myenv\lib\site-packages\urllib3\util\ssl_.py", line 344, in ssl_wrap_socket
    return context.wrap_socket(sock, server_hostname=server_hostname)
  File "c:\users\user\appdata\local\programs\python\python36\Lib\ssl.py", line 407, in wrap_socket
    _context=self, _session=session)
  File "c:\users\user\appdata\local\programs\python\python36\Lib\ssl.py", line 814, in __init__
    self.do_handshake()
  File "c:\users\user\appdata\local\programs\python\python36\Lib\ssl.py", line 1068, in do_handshake
    self._sslobj.do_handshake()
  File "c:\users\user\appdata\local\programs\python\python36\Lib\ssl.py", line 689, in do_handshake
    self._sslobj.do_handshake()
urllib3.exceptions.ProtocolError: ('Connection aborted.', ConnectionResetError(10054, 'An existing connection was forcibly closed by the remote host', None, 10054, None))

During handling of the above exception, another exception occurred:

Traceback (most recent call last):
  File "C:\Users\Desktop\Projects\Django Framework\Learn\ScrapeProject\myenv\lib\site-packages\django\core\handlers\exception.py", line 34, in inner
    response = get_response(request)
  File "C:\Users\Desktop\Projects\Django Framework\Learn\ScrapeProject\myenv\lib\site-packages\django\core\handlers\base.py", line 115, in _get_response
    response = self.process_exception_by_middleware(e, request)
  File "C:\Users\Desktop\Projects\Django Framework\Learn\ScrapeProject\myenv\lib\site-packages\django\core\handlers\base.py", line 113, in _get_response
    response = wrapped_callback(request, *callback_args, **callback_kwargs)
  File "C:\Users\Desktop\Projects\Django Framework\Learn\ScrapeProject\myenv\lib\site-packages\django\contrib\auth\decorators.py", line 21, in _wrapped_view
    return view_func(request, *args, **kwargs)
  File "C:\Users\Desktop\Projects\Django Framework\Learn\ScrapeProject\src\scraper\views.py", line 23, in Engine
    source = requests.get(src).text
  File "C:\Users\Desktop\Projects\Django Framework\Learn\ScrapeProject\myenv\lib\site-packages\requests\api.py", line 75, in get
    return request('get', url, params=params, **kwargs)
  File "C:\Users\Desktop\Projects\Django Framework\Learn\ScrapeProject\myenv\lib\site-packages\requests\api.py", line 60, in request
    return session.request(method=method, url=url, **kwargs)
  File "C:\Users\Desktop\Projects\Django Framework\Learn\ScrapeProject\myenv\lib\site-packages\requests\sessions.py", line 533, in request
    resp = self.send(prep, **send_kwargs)
  File "C:\Users\Desktop\Projects\Django Framework\Learn\ScrapeProject\myenv\lib\site-packages\requests\sessions.py", line 646, in send
    r = adapter.send(request, **kwargs)
  File "C:\Users\Desktop\Projects\Django Framework\Learn\ScrapeProject\myenv\lib\site-packages\requests\adapters.py", line 498, in send
    raise ConnectionError(err, request=request)
requests.exceptions.ConnectionError: ('Connection aborted.', ConnectionResetError(10054, 'An existing connection was forcibly closed by the remote host', None, 10054, None))
ERROR:django.request:Internal Server Error: /website/scraper/engine/
Traceback (most recent call last):
  File "C:\Users\Desktop\Projects\Django Framework\Learn\ScrapeProject\myenv\lib\site-packages\urllib3\connectionpool.py", line 600, in urlopen
    chunked=chunked)
  File "C:\Users\Desktop\Projects\Django Framework\Learn\ScrapeProject\myenv\lib\site-packages\urllib3\connectionpool.py", line 343, in _make_request
    self._validate_conn(conn)
  File "C:\Users\Desktop\Projects\Django Framework\Learn\ScrapeProject\myenv\lib\site-packages\urllib3\connectionpool.py", line 839, in _validate_conn
    conn.connect()
  File "C:\Users\Desktop\Projects\Django Framework\Learn\ScrapeProject\myenv\lib\site-packages\urllib3\connection.py", line 344, in connect
    ssl_context=context)
  File "C:\Users\Desktop\Projects\Django Framework\Learn\ScrapeProject\myenv\lib\site-packages\urllib3\util\ssl_.py", line 344, in ssl_wrap_socket
    return context.wrap_socket(sock, server_hostname=server_hostname)
  File "c:\users\user\appdata\local\programs\python\python36\Lib\ssl.py", line 407, in wrap_socket
    _context=self, _session=session)
  File "c:\users\user\appdata\local\programs\python\python36\Lib\ssl.py", line 814, in __init__
    self.do_handshake()
  File "c:\users\user\appdata\local\programs\python\python36\Lib\ssl.py", line 1068, in do_handshake
    self._sslobj.do_handshake()
  File "c:\users\user\appdata\local\programs\python\python36\Lib\ssl.py", line 689, in do_handshake
    self._sslobj.do_handshake()
ConnectionResetError: [WinError 10054] An existing connection was forcibly closed by the remote host

During handling of the above exception, another exception occurred:

Traceback (most recent call last):
  File "C:\Users\Desktop\Projects\Django Framework\Learn\ScrapeProject\myenv\lib\site-packages\requests\adapters.py", line 449, in send
    timeout=timeout
  File "C:\Users\Desktop\Projects\Django Framework\Learn\ScrapeProject\myenv\lib\site-packages\urllib3\connectionpool.py", line 638, in urlopen
    _stacktrace=sys.exc_info()[2])
  File "C:\Users\Desktop\Projects\Django Framework\Learn\ScrapeProject\myenv\lib\site-packages\urllib3\util\retry.py", line 367, in increment
    raise six.reraise(type(error), error, _stacktrace)
  File "C:\Users\Desktop\Projects\Django Framework\Learn\ScrapeProject\myenv\lib\site-packages\urllib3\packages\six.py", line 685, in reraise
    raise value.with_traceback(tb)
  File "C:\Users\Desktop\Projects\Django Framework\Learn\ScrapeProject\myenv\lib\site-packages\urllib3\connectionpool.py", line 600, in urlopen
    chunked=chunked)
  File "C:\Users\Desktop\Projects\Django Framework\Learn\ScrapeProject\myenv\lib\site-packages\urllib3\connectionpool.py", line 343, in _make_request
    self._validate_conn(conn)
  File "C:\Users\Desktop\Projects\Django Framework\Learn\ScrapeProject\myenv\lib\site-packages\urllib3\connectionpool.py", line 839, in _validate_conn
    conn.connect()
  File "C:\Users\Desktop\Projects\Django Framework\Learn\ScrapeProject\myenv\lib\site-packages\urllib3\connection.py", line 344, in connect
    ssl_context=context)
  File "C:\Users\Desktop\Projects\Django Framework\Learn\ScrapeProject\myenv\lib\site-packages\urllib3\util\ssl_.py", line 344, in ssl_wrap_socket
    return context.wrap_socket(sock, server_hostname=server_hostname)
  File "c:\users\user\appdata\local\programs\python\python36\Lib\ssl.py", line 407, in wrap_socket
    _context=self, _session=session)
  File "c:\users\user\appdata\local\programs\python\python36\Lib\ssl.py", line 814, in __init__
    self.do_handshake()
  File "c:\users\user\appdata\local\programs\python\python36\Lib\ssl.py", line 1068, in do_handshake
    self._sslobj.do_handshake()
  File "c:\users\user\appdata\local\programs\python\python36\Lib\ssl.py", line 689, in do_handshake
    self._sslobj.do_handshake()
urllib3.exceptions.ProtocolError: ('Connection aborted.', ConnectionResetError(10054, 'An existing connection was forcibly closed by the remote host', None, 10054, None))

During handling of the above exception, another exception occurred:

Traceback (most recent call last):
  File "C:\Users\Desktop\Projects\Django Framework\Learn\ScrapeProject\myenv\lib\site-packages\django\core\handlers\exception.py", line 34, in inner
    response = get_response(request)
  File "C:\Users\Desktop\Projects\Django Framework\Learn\ScrapeProject\myenv\lib\site-packages\django\core\handlers\base.py", line 115, in _get_response
    response = self.process_exception_by_middleware(e, request)
  File "C:\Users\Desktop\Projects\Django Framework\Learn\ScrapeProject\myenv\lib\site-packages\django\core\handlers\base.py", line 113, in _get_response
    response = wrapped_callback(request, *callback_args, **callback_kwargs)
  File "C:\Users\Desktop\Projects\Django Framework\Learn\ScrapeProject\myenv\lib\site-packages\django\contrib\auth\decorators.py", line 21, in _wrapped_view
    return view_func(request, *args, **kwargs)
  File "C:\Users\Desktop\Projects\Django Framework\Learn\ScrapeProject\src\scraper\views.py", line 23, in Engine
    source = requests.get(src).text
  File "C:\Users\Desktop\Projects\Django Framework\Learn\ScrapeProject\myenv\lib\site-packages\requests\api.py", line 75, in get
    return request('get', url, params=params, **kwargs)
  File "C:\Users\Desktop\Projects\Django Framework\Learn\ScrapeProject\myenv\lib\site-packages\requests\api.py", line 60, in request
    return session.request(method=method, url=url, **kwargs)
  File "C:\Users\Desktop\Projects\Django Framework\Learn\ScrapeProject\myenv\lib\site-packages\requests\sessions.py", line 533, in request
    resp = self.send(prep, **send_kwargs)
  File "C:\Users\Desktop\Projects\Django Framework\Learn\ScrapeProject\myenv\lib\site-packages\requests\sessions.py", line 646, in send
    r = adapter.send(request, **kwargs)
  File "C:\Users\Desktop\Projects\Django Framework\Learn\ScrapeProject\myenv\lib\site-packages\requests\adapters.py", line 498, in send
    raise ConnectionError(err, request=request)
requests.exceptions.ConnectionError: ('Connection aborted.', ConnectionResetError(10054, 'An existing connection was forcibly closed by the remote host', None, 10054, None))
ERROR:django.request:Internal Server Error: /website/scraper/engine/
Traceback (most recent call last):
  File "C:\Users\Desktop\Projects\Django Framework\Learn\ScrapeProject\myenv\lib\site-packages\urllib3\connectionpool.py", line 600, in urlopen
    chunked=chunked)
  File "C:\Users\Desktop\Projects\Django Framework\Learn\ScrapeProject\myenv\lib\site-packages\urllib3\connectionpool.py", line 343, in _make_request
    self._validate_conn(conn)
  File "C:\Users\Desktop\Projects\Django Framework\Learn\ScrapeProject\myenv\lib\site-packages\urllib3\connectionpool.py", line 839, in _validate_conn
    conn.connect()
  File "C:\Users\Desktop\Projects\Django Framework\Learn\ScrapeProject\myenv\lib\site-packages\urllib3\connection.py", line 344, in connect
    ssl_context=context)
  File "C:\Users\Desktop\Projects\Django Framework\Learn\ScrapeProject\myenv\lib\site-packages\urllib3\util\ssl_.py", line 344, in ssl_wrap_socket
    return context.wrap_socket(sock, server_hostname=server_hostname)
  File "c:\users\user\appdata\local\programs\python\python36\Lib\ssl.py", line 407, in wrap_socket
    _context=self, _session=session)
  File "c:\users\user\appdata\local\programs\python\python36\Lib\ssl.py", line 814, in __init__
    self.do_handshake()
  File "c:\users\user\appdata\local\programs\python\python36\Lib\ssl.py", line 1068, in do_handshake
    self._sslobj.do_handshake()
  File "c:\users\user\appdata\local\programs\python\python36\Lib\ssl.py", line 689, in do_handshake
    self._sslobj.do_handshake()
ConnectionResetError: [WinError 10054] An existing connection was forcibly closed by the remote host

During handling of the above exception, another exception occurred:

Traceback (most recent call last):
  File "C:\Users\Desktop\Projects\Django Framework\Learn\ScrapeProject\myenv\lib\site-packages\requests\adapters.py", line 449, in send
    timeout=timeout
  File "C:\Users\Desktop\Projects\Django Framework\Learn\ScrapeProject\myenv\lib\site-packages\urllib3\connectionpool.py", line 638, in urlopen
    _stacktrace=sys.exc_info()[2])
  File "C:\Users\Desktop\Projects\Django Framework\Learn\ScrapeProject\myenv\lib\site-packages\urllib3\util\retry.py", line 367, in increment
    raise six.reraise(type(error), error, _stacktrace)
  File "C:\Users\Desktop\Projects\Django Framework\Learn\ScrapeProject\myenv\lib\site-packages\urllib3\packages\six.py", line 685, in reraise
    raise value.with_traceback(tb)
  File "C:\Users\Desktop\Projects\Django Framework\Learn\ScrapeProject\myenv\lib\site-packages\urllib3\connectionpool.py", line 600, in urlopen
    chunked=chunked)
  File "C:\Users\Desktop\Projects\Django Framework\Learn\ScrapeProject\myenv\lib\site-packages\urllib3\connectionpool.py", line 343, in _make_request
    self._validate_conn(conn)
  File "C:\Users\Desktop\Projects\Django Framework\Learn\ScrapeProject\myenv\lib\site-packages\urllib3\connectionpool.py", line 839, in _validate_conn
    conn.connect()
  File "C:\Users\Desktop\Projects\Django Framework\Learn\ScrapeProject\myenv\lib\site-packages\urllib3\connection.py", line 344, in connect
    ssl_context=context)
  File "C:\Users\Desktop\Projects\Django Framework\Learn\ScrapeProject\myenv\lib\site-packages\urllib3\util\ssl_.py", line 344, in ssl_wrap_socket
    return context.wrap_socket(sock, server_hostname=server_hostname)
  File "c:\users\user\appdata\local\programs\python\python36\Lib\ssl.py", line 407, in wrap_socket
    _context=self, _session=session)
  File "c:\users\user\appdata\local\programs\python\python36\Lib\ssl.py", line 814, in __init__
    self.do_handshake()
  File "c:\users\user\appdata\local\programs\python\python36\Lib\ssl.py", line 1068, in do_handshake
    self._sslobj.do_handshake()
  File "c:\users\user\appdata\local\programs\python\python36\Lib\ssl.py", line 689, in do_handshake
    self._sslobj.do_handshake()
urllib3.exceptions.ProtocolError: ('Connection aborted.', ConnectionResetError(10054, 'An existing connection was forcibly closed by the remote host', None, 10054, None))

During handling of the above exception, another exception occurred:

Traceback (most recent call last):
  File "C:\Users\Desktop\Projects\Django Framework\Learn\ScrapeProject\myenv\lib\site-packages\django\core\handlers\exception.py", line 34, in inner
    response = get_response(request)
  File "C:\Users\Desktop\Projects\Django Framework\Learn\ScrapeProject\myenv\lib\site-packages\django\core\handlers\base.py", line 115, in _get_response
    response = self.process_exception_by_middleware(e, request)
  File "C:\Users\Desktop\Projects\Django Framework\Learn\ScrapeProject\myenv\lib\site-packages\django\core\handlers\base.py", line 113, in _get_response
    response = wrapped_callback(request, *callback_args, **callback_kwargs)
  File "C:\Users\Desktop\Projects\Django Framework\Learn\ScrapeProject\myenv\lib\site-packages\django\contrib\auth\decorators.py", line 21, in _wrapped_view
    return view_func(request, *args, **kwargs)
  File "C:\Users\Desktop\Projects\Django Framework\Learn\ScrapeProject\src\scraper\views.py", line 23, in Engine
    source = requests.get(src).text
  File "C:\Users\Desktop\Projects\Django Framework\Learn\ScrapeProject\myenv\lib\site-packages\requests\api.py", line 75, in get
    return request('get', url, params=params, **kwargs)
  File "C:\Users\Desktop\Projects\Django Framework\Learn\ScrapeProject\myenv\lib\site-packages\requests\api.py", line 60, in request
    return session.request(method=method, url=url, **kwargs)
  File "C:\Users\Desktop\Projects\Django Framework\Learn\ScrapeProject\myenv\lib\site-packages\requests\sessions.py", line 533, in request
    resp = self.send(prep, **send_kwargs)
  File "C:\Users\Desktop\Projects\Django Framework\Learn\ScrapeProject\myenv\lib\site-packages\requests\sessions.py", line 646, in send
    r = adapter.send(request, **kwargs)
  File "C:\Users\Desktop\Projects\Django Framework\Learn\ScrapeProject\myenv\lib\site-packages\requests\adapters.py", line 498, in send
    raise ConnectionError(err, request=request)
requests.exceptions.ConnectionError: ('Connection aborted.', ConnectionResetError(10054, 'An existing connection was forcibly closed by the remote host', None, 10054, None))
ERROR:django.request:Internal Server Error: /website/scraper/engine/
Traceback (most recent call last):
  File "C:\Users\Desktop\Projects\Django Framework\Learn\ScrapeProject\myenv\lib\site-packages\urllib3\connectionpool.py", line 600, in urlopen
    chunked=chunked)
  File "C:\Users\Desktop\Projects\Django Framework\Learn\ScrapeProject\myenv\lib\site-packages\urllib3\connectionpool.py", line 343, in _make_request
    self._validate_conn(conn)
  File "C:\Users\Desktop\Projects\Django Framework\Learn\ScrapeProject\myenv\lib\site-packages\urllib3\connectionpool.py", line 839, in _validate_conn
    conn.connect()
  File "C:\Users\Desktop\Projects\Django Framework\Learn\ScrapeProject\myenv\lib\site-packages\urllib3\connection.py", line 344, in connect
    ssl_context=context)
  File "C:\Users\Desktop\Projects\Django Framework\Learn\ScrapeProject\myenv\lib\site-packages\urllib3\util\ssl_.py", line 344, in ssl_wrap_socket
    return context.wrap_socket(sock, server_hostname=server_hostname)
  File "c:\users\user\appdata\local\programs\python\python36\Lib\ssl.py", line 407, in wrap_socket
    _context=self, _session=session)
  File "c:\users\user\appdata\local\programs\python\python36\Lib\ssl.py", line 814, in __init__
    self.do_handshake()
  File "c:\users\user\appdata\local\programs\python\python36\Lib\ssl.py", line 1068, in do_handshake
    self._sslobj.do_handshake()
  File "c:\users\user\appdata\local\programs\python\python36\Lib\ssl.py", line 689, in do_handshake
    self._sslobj.do_handshake()
ConnectionResetError: [WinError 10054] An existing connection was forcibly closed by the remote host

During handling of the above exception, another exception occurred:

Traceback (most recent call last):
  File "C:\Users\Desktop\Projects\Django Framework\Learn\ScrapeProject\myenv\lib\site-packages\requests\adapters.py", line 449, in send
    timeout=timeout
  File "C:\Users\Desktop\Projects\Django Framework\Learn\ScrapeProject\myenv\lib\site-packages\urllib3\connectionpool.py", line 638, in urlopen
    _stacktrace=sys.exc_info()[2])
  File "C:\Users\Desktop\Projects\Django Framework\Learn\ScrapeProject\myenv\lib\site-packages\urllib3\util\retry.py", line 367, in increment
    raise six.reraise(type(error), error, _stacktrace)
  File "C:\Users\Desktop\Projects\Django Framework\Learn\ScrapeProject\myenv\lib\site-packages\urllib3\packages\six.py", line 685, in reraise
    raise value.with_traceback(tb)
  File "C:\Users\Desktop\Projects\Django Framework\Learn\ScrapeProject\myenv\lib\site-packages\urllib3\connectionpool.py", line 600, in urlopen
    chunked=chunked)
  File "C:\Users\Desktop\Projects\Django Framework\Learn\ScrapeProject\myenv\lib\site-packages\urllib3\connectionpool.py", line 343, in _make_request
    self._validate_conn(conn)
  File "C:\Users\Desktop\Projects\Django Framework\Learn\ScrapeProject\myenv\lib\site-packages\urllib3\connectionpool.py", line 839, in _validate_conn
    conn.connect()
  File "C:\Users\Desktop\Projects\Django Framework\Learn\ScrapeProject\myenv\lib\site-packages\urllib3\connection.py", line 344, in connect
    ssl_context=context)
  File "C:\Users\Desktop\Projects\Django Framework\Learn\ScrapeProject\myenv\lib\site-packages\urllib3\util\ssl_.py", line 344, in ssl_wrap_socket
    return context.wrap_socket(sock, server_hostname=server_hostname)
  File "c:\users\user\appdata\local\programs\python\python36\Lib\ssl.py", line 407, in wrap_socket
    _context=self, _session=session)
  File "c:\users\user\appdata\local\programs\python\python36\Lib\ssl.py", line 814, in __init__
    self.do_handshake()
  File "c:\users\user\appdata\local\programs\python\python36\Lib\ssl.py", line 1068, in do_handshake
    self._sslobj.do_handshake()
  File "c:\users\user\appdata\local\programs\python\python36\Lib\ssl.py", line 689, in do_handshake
    self._sslobj.do_handshake()
urllib3.exceptions.ProtocolError: ('Connection aborted.', ConnectionResetError(10054, 'An existing connection was forcibly closed by the remote host', None, 10054, None))

During handling of the above exception, another exception occurred:

Traceback (most recent call last):
  File "C:\Users\Desktop\Projects\Django Framework\Learn\ScrapeProject\myenv\lib\site-packages\django\core\handlers\exception.py", line 34, in inner
    response = get_response(request)
  File "C:\Users\Desktop\Projects\Django Framework\Learn\ScrapeProject\myenv\lib\site-packages\django\core\handlers\base.py", line 115, in _get_response
    response = self.process_exception_by_middleware(e, request)
  File "C:\Users\Desktop\Projects\Django Framework\Learn\ScrapeProject\myenv\lib\site-packages\django\core\handlers\base.py", line 113, in _get_response
    response = wrapped_callback(request, *callback_args, **callback_kwargs)
  File "C:\Users\Desktop\Projects\Django Framework\Learn\ScrapeProject\myenv\lib\site-packages\django\contrib\auth\decorators.py", line 21, in _wrapped_view
    return view_func(request, *args, **kwargs)
  File "C:\Users\Desktop\Projects\Django Framework\Learn\ScrapeProject\src\scraper\views.py", line 23, in Engine
    source = requests.get(src).text
  File "C:\Users\Desktop\Projects\Django Framework\Learn\ScrapeProject\myenv\lib\site-packages\requests\api.py", line 75, in get
    return request('get', url, params=params, **kwargs)
  File "C:\Users\Desktop\Projects\Django Framework\Learn\ScrapeProject\myenv\lib\site-packages\requests\api.py", line 60, in request
    return session.request(method=method, url=url, **kwargs)
  File "C:\Users\Desktop\Projects\Django Framework\Learn\ScrapeProject\myenv\lib\site-packages\requests\sessions.py", line 533, in request
    resp = self.send(prep, **send_kwargs)
  File "C:\Users\Desktop\Projects\Django Framework\Learn\ScrapeProject\myenv\lib\site-packages\requests\sessions.py", line 646, in send
    r = adapter.send(request, **kwargs)
  File "C:\Users\Desktop\Projects\Django Framework\Learn\ScrapeProject\myenv\lib\site-packages\requests\adapters.py", line 498, in send
    raise ConnectionError(err, request=request)
requests.exceptions.ConnectionError: ('Connection aborted.', ConnectionResetError(10054, 'An existing connection was forcibly closed by the remote host', None, 10054, None))
ERROR:django.request:Internal Server Error: /website/scraper/engine/
Traceback (most recent call last):
  File "C:\Users\Desktop\Projects\Django Framework\Learn\ScrapeProject\myenv\lib\site-packages\urllib3\connectionpool.py", line 600, in urlopen
    chunked=chunked)
  File "C:\Users\Desktop\Projects\Django Framework\Learn\ScrapeProject\myenv\lib\site-packages\urllib3\connectionpool.py", line 343, in _make_request
    self._validate_conn(conn)
  File "C:\Users\Desktop\Projects\Django Framework\Learn\ScrapeProject\myenv\lib\site-packages\urllib3\connectionpool.py", line 839, in _validate_conn
    conn.connect()
  File "C:\Users\Desktop\Projects\Django Framework\Learn\ScrapeProject\myenv\lib\site-packages\urllib3\connection.py", line 344, in connect
    ssl_context=context)
  File "C:\Users\Desktop\Projects\Django Framework\Learn\ScrapeProject\myenv\lib\site-packages\urllib3\util\ssl_.py", line 344, in ssl_wrap_socket
    return context.wrap_socket(sock, server_hostname=server_hostname)
  File "c:\users\user\appdata\local\programs\python\python36\Lib\ssl.py", line 407, in wrap_socket
    _context=self, _session=session)
  File "c:\users\user\appdata\local\programs\python\python36\Lib\ssl.py", line 814, in __init__
    self.do_handshake()
  File "c:\users\user\appdata\local\programs\python\python36\Lib\ssl.py", line 1068, in do_handshake
    self._sslobj.do_handshake()
  File "c:\users\user\appdata\local\programs\python\python36\Lib\ssl.py", line 689, in do_handshake
    self._sslobj.do_handshake()
ConnectionResetError: [WinError 10054] An existing connection was forcibly closed by the remote host

During handling of the above exception, another exception occurred:

Traceback (most recent call last):
  File "C:\Users\Desktop\Projects\Django Framework\Learn\ScrapeProject\myenv\lib\site-packages\requests\adapters.py", line 449, in send
    timeout=timeout
  File "C:\Users\Desktop\Projects\Django Framework\Learn\ScrapeProject\myenv\lib\site-packages\urllib3\connectionpool.py", line 638, in urlopen
    _stacktrace=sys.exc_info()[2])
  File "C:\Users\Desktop\Projects\Django Framework\Learn\ScrapeProject\myenv\lib\site-packages\urllib3\util\retry.py", line 367, in increment
    raise six.reraise(type(error), error, _stacktrace)
  File "C:\Users\Desktop\Projects\Django Framework\Learn\ScrapeProject\myenv\lib\site-packages\urllib3\packages\six.py", line 685, in reraise
    raise value.with_traceback(tb)
  File "C:\Users\Desktop\Projects\Django Framework\Learn\ScrapeProject\myenv\lib\site-packages\urllib3\connectionpool.py", line 600, in urlopen
    chunked=chunked)
  File "C:\Users\Desktop\Projects\Django Framework\Learn\ScrapeProject\myenv\lib\site-packages\urllib3\connectionpool.py", line 343, in _make_request
    self._validate_conn(conn)
  File "C:\Users\Desktop\Projects\Django Framework\Learn\ScrapeProject\myenv\lib\site-packages\urllib3\connectionpool.py", line 839, in _validate_conn
    conn.connect()
  File "C:\Users\Desktop\Projects\Django Framework\Learn\ScrapeProject\myenv\lib\site-packages\urllib3\connection.py", line 344, in connect
    ssl_context=context)
  File "C:\Users\Desktop\Projects\Django Framework\Learn\ScrapeProject\myenv\lib\site-packages\urllib3\util\ssl_.py", line 344, in ssl_wrap_socket
    return context.wrap_socket(sock, server_hostname=server_hostname)
  File "c:\users\user\appdata\local\programs\python\python36\Lib\ssl.py", line 407, in wrap_socket
    _context=self, _session=session)
  File "c:\users\user\appdata\local\programs\python\python36\Lib\ssl.py", line 814, in __init__
    self.do_handshake()
  File "c:\users\user\appdata\local\programs\python\python36\Lib\ssl.py", line 1068, in do_handshake
    self._sslobj.do_handshake()
  File "c:\users\user\appdata\local\programs\python\python36\Lib\ssl.py", line 689, in do_handshake
    self._sslobj.do_handshake()
urllib3.exceptions.ProtocolError: ('Connection aborted.', ConnectionResetError(10054, 'An existing connection was forcibly closed by the remote host', None, 10054, None))

During handling of the above exception, another exception occurred:

Traceback (most recent call last):
  File "C:\Users\Desktop\Projects\Django Framework\Learn\ScrapeProject\myenv\lib\site-packages\django\core\handlers\exception.py", line 34, in inner
    response = get_response(request)
  File "C:\Users\Desktop\Projects\Django Framework\Learn\ScrapeProject\myenv\lib\site-packages\django\core\handlers\base.py", line 115, in _get_response
    response = self.process_exception_by_middleware(e, request)
  File "C:\Users\Desktop\Projects\Django Framework\Learn\ScrapeProject\myenv\lib\site-packages\django\core\handlers\base.py", line 113, in _get_response
    response = wrapped_callback(request, *callback_args, **callback_kwargs)
  File "C:\Users\Desktop\Projects\Django Framework\Learn\ScrapeProject\myenv\lib\site-packages\django\contrib\auth\decorators.py", line 21, in _wrapped_view
    return view_func(request, *args, **kwargs)
  File "C:\Users\Desktop\Projects\Django Framework\Learn\ScrapeProject\src\scraper\views.py", line 23, in Engine
    source = requests.get(src).text
  File "C:\Users\Desktop\Projects\Django Framework\Learn\ScrapeProject\myenv\lib\site-packages\requests\api.py", line 75, in get
    return request('get', url, params=params, **kwargs)
  File "C:\Users\Desktop\Projects\Django Framework\Learn\ScrapeProject\myenv\lib\site-packages\requests\api.py", line 60, in request
    return session.request(method=method, url=url, **kwargs)
  File "C:\Users\Desktop\Projects\Django Framework\Learn\ScrapeProject\myenv\lib\site-packages\requests\sessions.py", line 533, in request
    resp = self.send(prep, **send_kwargs)
  File "C:\Users\Desktop\Projects\Django Framework\Learn\ScrapeProject\myenv\lib\site-packages\requests\sessions.py", line 646, in send
    r = adapter.send(request, **kwargs)
  File "C:\Users\Desktop\Projects\Django Framework\Learn\ScrapeProject\myenv\lib\site-packages\requests\adapters.py", line 498, in send
    raise ConnectionError(err, request=request)
requests.exceptions.ConnectionError: ('Connection aborted.', ConnectionResetError(10054, 'An existing connection was forcibly closed by the remote host', None, 10054, None))
INFO:django.utils.autoreload:C:\Users\Desktop\Projects\Django Framework\Learn\ScrapeProject\src\scraper\views.py changed, reloading.
INFO:django.utils.autoreload:C:\Users\Desktop\Projects\Django Framework\Learn\ScrapeProject\src\scraper\views.py changed, reloading.
